commit 23fcae7c9e2969cf6c9ffb019dda90e2abce2337
Author: Brian Goad <bdgoad@gmail.com>
Date:   Mon Jun 24 11:58:04 2019 -0400

    Fix issue with displaying error about unreachable hosts when using Unixy Callback (#58076)

diff --git a/lib/ansible/plugins/callback/unixy.py b/lib/ansible/plugins/callback/unixy.py
index baa0bc6595..ea2fea53a0 100644
--- a/lib/ansible/plugins/callback/unixy.py
+++ b/lib/ansible/plugins/callback/unixy.py
@@ -149,6 +149,8 @@ class CallbackModule(CallbackModule_default):
         self.v2_runner_on_ok(result)
 
     def v2_runner_on_unreachable(self, result):
+        self._preprocess_result(result)
+
         msg = "unreachable"
         display_color = C.COLOR_UNREACHABLE
         task_result = self._process_result_output(result, msg)
